Workbook
Name 切片器_类别: #N/A
Name 切片器_类别1: #N/A

Sheet Sheet1
A1: 怪物等级 | B1: 血量加成 | C1: 伤害加成 | D1: 法伤加成 | E1: 速度加成 | F1: 防御加成 | G1: 法防加成 | I1: 伤害 | J1: 气血 | K1: 灵力 | L1: 速度 | M1: 防御 | N1: 法防 | O1: 法伤 | P1: 魔法 | Q1: 体质 | R1: 魔力 | S1: 力量 | T1: 耐力 | U1: 敏捷 | V1: 修炼加成
A2: 170 | B2: 5 | C2: 1.5 | D2: 2.5 | E2: 1 | F2: 1 | G2: 1 | H2: 无修炼 | I2: =INT(VLOOKUP(A2,Sheet2!A2:N22,2,0)*C2) -> 3825 | J2: =VLOOKUP(A2,Sheet2!A2:N22,3,0)*B2 -> 12750 | K2: =VLOOKUP(A2,Sheet2!A2:N22,4,0) -> 0 | L2: =VLOOKUP(A2,Sheet2!A2:N22,5,0)*E2 -> 340 | M2: =INT(VLOOKUP(A2,Sheet2!A2:N22,6,0)*F2) -> 1020 | N2: =INT(VLOOKUP(A2,Sheet2!A2:N22,7,0)*G2) -> 680 | O2: =INT(VLOOKUP(A2,Sheet2!A2:N22,8,0)*D2) -> 3400 | P2: =VLOOKUP(A2,Sheet2!A2:N22,9,0) -> 1800 | Q2: =VLOOKUP(A2,Sheet2!A2:N22,10,0) -> 384 | R2: =VLOOKUP(A2,Sheet2!A2:N22,11,0) -> 384 | S2: =VLOOKUP(A2,Sheet2!A2:N22,12,0) -> 850 | T2: =VLOOKUP(A2,Sheet2!A2:N22,13,0) -> 384 | U2: =VLOOKUP(A2,Sheet2!A2:N22,14,0) -> 384 | V2: =VLOOKUP(A2,Sheet2!A2:O22,15,0) -> 25
A5: 人物等级 | C5: 强身 | D5: 冥想
A6: 174 | C6: 1 | D6: 1 | I6: 伤害 | J6: 命中 | K6: 气血 | L6: 灵力 | M6: 速度 | N6: 防御 | O6: 法防 | P6: 法伤 | Q6: 魔法 | R6: 体质 | S6: 魔力 | T6: 力量 | U6: 耐力 | V6: 敏捷 | W6: 修
A7: 种族 | B7: 命中系数 | C7: 伤害系数 | D7: 防御系数 | E7: 气血系数 | F7: 法力系数 | G7: 加点方式 | H7: 有修装备小 | I7: =INT(VLOOKUP(A6,Sheet2!A27:N202,4,0)+(T7*C8+B10)+(J7/3)+E10) -> 1555 | J7: =VLOOKUP(A6,Sheet2!A27:N202,2,0)+(T7*B8+A10)+G10 -> 1404 | K7: =VLOOKUP(A6,Sheet2!A27:N202,10,0)+(T7*E8+100)+B12 -> 1349 | L7: =VLOOKUP(A6,Sheet2!A27:N202,8,0)+(R7*0.3+S7*0.7+T7*0.3+U7*0.2)+D10 -> 1516 | M7: =INT(VLOOKUP(A6,Sheet2!A27:N202,12,0)*0.7+(R7*0.1+T7*0.1+U7*0.1+V7*0.7))+A12 -> 220 | N7: =INT(VLOOKUP(A6,Sheet2!A27:N202,6,0)+(U7*D8))+F10 -> 1212 | O7: =L7 -> 1516 | P7: =L7 -> 1516 | Q7: =VLOOKUP(A6,Sheet2!A27:N202,14,0)+(S7*F8)+C12 -> 3386 | R7: =VLOOKUP(G8,Sheet2!A208:F224,2,0)*A6+10 -> 184 | S7: =VLOOKUP(G8,Sheet2!A208:F224,3,0)*A6+10 -> 1054 | T7: =VLOOKUP(G8,Sheet2!A208:F224,4,0)*A6+10 -> 184 | U7: =VLOOKUP(G8,Sheet2!A208:F224,5,0)*A6+10 -> 184 | V7: =VLOOKUP(G8,Sheet2!A208:F224,6,0)*A6+10 -> 184 | W7: =VLOOKUP(A6,Sheet2!A27:AI202,35,0) -> 25
A8: 人 | B8: =VLOOKUP(A8,Sheet2!A204:F206,2,0) -> 2 | C8: =VLOOKUP(A8,Sheet2!A204:F206,3,0) -> 0.7 | D8: =VLOOKUP(A8,Sheet2!A204:F206,4,0) -> 1.5 | E8: =VLOOKUP(A8,Sheet2!A204:F206,5,0) -> 5 | F8: =VLOOKUP(A8,Sheet2!A204:F206,6,0) -> 3 | G8: 全魔 | H8: 有修装备大 | I8: =INT((VLOOKUP(A6,Sheet2!A27:N202,5,0)+(T8*C8+B10)+(J8/3))+E10) -> 1801 | J8: =VLOOKUP(A6,Sheet2!A27:N202,3,0)+(T7*B8+A10)+G10 -> 1610 | K8: =VLOOKUP(A6,Sheet2!A27:N202,11,0)+(T7*E8+100)+B12 -> 1469 | L8: =VLOOKUP(A6,Sheet2!A27:N202,9,0)+(R7*0.3+S7*0.7+T7*0.3+U7*0.2)+D10 -> 1587 | M8: =INT(VLOOKUP(A6,Sheet2!A27:N202,13,0)*0.7+(R7*0.1+T7*0.1+U7*0.1+V7*0.7))+A12 -> 233 | N8: =INT(VLOOKUP(A6,Sheet2!A27:N202,7,0)+(U7*D8))+F10 -> 1396 | O8: =L8 -> 1587 | P8: =L8 -> 1587 | Q8: =VLOOKUP(A6,Sheet2!A27:N202,14,0)+(S7*F8)+C12 -> 3386 | R8: =VLOOKUP(G8,Sheet2!A208:F224,2,0)*A6+10 -> 184 | S8: =VLOOKUP(G8,Sheet2!A208:F224,3,0)*A6+10 -> 1054 | T8: =VLOOKUP(G8,Sheet2!A208:F224,4,0)*A6+10 -> 184 | U8: =VLOOKUP(G8,Sheet2!A208:F224,5,0)*A6+10 -> 184 | V8: =VLOOKUP(G8,Sheet2!A208:F224,6,0)*A6+10 -> 184 | W8: =VLOOKUP(A6,Sheet2!A27:AI202,35,0) -> 25
A9: 附加命中 | B9: 附加伤害 | C9: 门派 | D9: 灵力 | E9: 伤害 | F9: 防御 | G9: 命中
A10: =VLOOKUP(A8,Sheet2!A204:H206,7,0) -> 30 | B10: =VLOOKUP(A8,Sheet2!A204:H206,8,0) -> 34 | C10: 大唐官府 | D10: =VLOOKUP(C10,Sheet2!A226:H240,2,0)*A6 -> 435 | E10: =VLOOKUP(C10,Sheet2!A226:H240,3,0)*A6 -> 435 | F10: =VLOOKUP(C10,Sheet2!A226:H240,4,0)*A6 -> 435 | G10: =VLOOKUP(C10,Sheet2!A226:H240,5,0)*A6 -> 435
A11: 速度 | B11: 气血 | C11: 魔法
A12: =VLOOKUP(C10,Sheet2!A226:H240,6,0)*A6 -> 0 | B12: =VLOOKUP(C10,Sheet2!A226:H240,7,0)*A6 -> 0 | C12: =VLOOKUP(C10,Sheet2!A226:H240,8,0)*A6 -> 0
A13: 类别 | B13: 满修-最大 | G13: 类别 | H13: 没修-最小
A15: 行标签 | B15: 求和项:怪物输出 | C15: 求和项:怪物暴击 | G15: 行标签 | H15: 求和项:角色输出 | I15: 求和项:角色暴击
A16: 单法伤害 | B16: 2458 | C16: 4916 | G16: 单法伤害 | H16: 2196 | I16: 4392
A17: 飞砂秒1 | B17: 2135 | C17: 4056 | G17: 飞砂秒1 | H17: 1862 | I17: 3537
A18: 飞砂秒2 | B18: 1898 | C18: 4934 | G18: 飞砂秒2 | H18: 1655 | I18: 4303
A19: 飞砂秒3 | B19: 1661 | C19: 5149 | G19: 飞砂秒3 | H19: 1448 | I19: 4488
A20: 飞砂秒4 | B20: 1423 | C20: 4838 | G20: 飞砂秒4 | H20: 837 | I20: 2845
A21: 飞砂秒5 | B21: 1423 | C21: 4980 | G21: 飞砂秒5 | H21: 1241 | I21: 4343
A22: 龙卷秒1 | B22: 2135 | C22: 4056 | G22: 龙卷秒1 | H22: 1862 | I22: 3537
A23: 龙卷秒10 | B23: 949 | C23: 4745 | G23: 龙卷秒10 | H23: 827 | I23: 4135
A24: 龙卷秒2 | B24: 1898 | C24: 4934 | G24: 龙卷秒2 | H24: 1655 | I24: 4303
A25: 龙卷秒3 | B25: 1661 | C25: 5149 | G25: 龙卷秒3 | H25: 977 | I25: 3028
A26: 龙卷秒4 | B26: 1423 | C26: 4838 | G26: 龙卷秒4 | H26: 1241 | I26: 4219
A27: 龙卷秒5 | B27: 1186 | C27: 4151 | G27: 龙卷秒5 | H27: 1034 | I27: 3619
... A33: 总计 | B33: 26999 | C33: 80135 | G33: 总计 | H33: 21409 | I33: 64519
A41: 类别 | B41: 分类 | C41: 怪物输出 | D41: 怪物暴击 | E41: 角色输出 | F41: 角色暴击
A42: 满修-最小 | B42: 物理输出 | C42: =INT(($I$2-$N$7)*(1+(($V$2-$W$7)/100*2))+($V$2*2)) -> 2663 | D42: =C42*2 -> 5326 | E42: =INT(($I$7-$M$2)*(1+(($W$7-$V$2)/100*2))+($W$7*2)) -> 585 | F42: =E42*2 -> 1170
A43: 满修-最小 | B43: 单法伤害 | C43: =INT(($A$2*3.5+$K$2+$O$2-$O$7)*(1+(($V$2-$W$7)/100*2))+($V$2*2)) -> 2529 | D43: =C43*2 -> 5058 | E43: =INT(($A$2*3.5+$P$7-$N$2)*(1+(($W$7-$V$2)/100*2))+($W$7*2)) -> 1481 | F43: =E43*2 -> 2962
A44: 满修-最小 | B44: 飞砂秒1 | C44: =INT((($A$2*3+$K$2+$O$2-$O$7)*(1+(($V$2-$W$7)/100*2))+($V$2*2))*0.9) -> 2199 | D44: =INT(C44*1.9) -> 4178 | E44: =INT((($A$2*3+$P$7-$N$2)*(1+(($W$7-$V$2)/100*2))+($W$7*2))*0.9) -> 1256 | F44: =INT(E44*1.9) -> 2386
A45: 满修-最小 | B45: 飞砂秒2 | C45: =INT((($A$2*3+$K$2+$O$2-$O$7)*(1+(($V$2-$W$7)/100*2))+($V$2*2))*0.8) -> 1955 | D45: =INT(C45*2.6) -> 5083 | E45: =INT((($A$2*3+$P$7-$N$2)*(1+(($W$7-$V$2)/100*2))+($W$7*2))*0.8) -> 1116 | F45: =INT(E45*2.6) -> 2901
A46: 满修-最小 | B46: 飞砂秒3 | C46: =INT((($A$2*3+$K$2+$O$2-$O$7)*(1+(($V$2-$W$7)/100*2))+($V$2*2))*0.7) -> 1710 | D46: =INT(C46*3.1) -> 5301 | E46: =INT((($A$2*3+$P$7-$N$2)*(1+(($W$7-$V$2)/100*2))+($W$7*2))*0.7) -> 977 | F46: =INT(E46*3.1) -> 3028
A47: 满修-最小 | B47: 飞砂秒4 | C47: =INT((($A$2*3+$K$2+$O$2-$O$7)*(1+(($V$2-$W$7)/100*2))+($V$2*2))*0.6) -> 1466 | D47: =INT(C47*3.4) -> 4984 | E47: =INT((($A$2*3+$P$7-$N$2)*(1+(($W$7-$V$2)/100*2))+($W$7*2))*0.6) -> 837 | F47: =INT(E47*3.4) -> 2845
A48: 满修-最小 | B48: 飞砂秒5 | C48: =INT((($A$2*3+$K$2+$O$2-$O$7)*(1+(($V$2-$W$7)/100*2))+($V$2*2))*0.6) -> 1466 | D48: =INT(C48*3.5) -> 5131 | E48: =INT((($A$2*3+$P$7-$N$2)*(1+(($W$7-$V$2)/100*2))+($W$7*2))*0.6) -> 837 | F48: =INT(E48*3.5) -> 2929
A49: 满修-最小 | B49: 龙卷秒1 | C49: =INT((($A$2*3+$K$2+$O$2-$O$7)*(1+(($V$2-$W$7)/100*2))+($V$2*2))*0.9) -> 2199 | D49: =INT(C49*1.9) -> 4178 | E49: =INT((($A$2*3+$P$7-$N$2)*(1+(($W$7-$V$2)/100*2))+($W$7*2))*0.9) -> 1256 | F49: =INT(E49*1.9) -> 2386
A50: 满修-最小 | B50: 龙卷秒2 | C50: =INT((($A$2*3+$K$2+$O$2-$O$7)*(1+(($V$2-$W$7)/100*2))+($V$2*2))*0.8) -> 1955 | D50: =INT(C50*2.6) -> 5083 | E50: =INT((($A$2*3+$P$7-$N$2)*(1+(($W$7-$V$2)/100*2))+($W$7*2))*0.8) -> 1116 | F50: =INT(E50*2.6) -> 2901
A51: 满修-最小 | B51: 龙卷秒3 | C51: =INT((($A$2*3+$K$2+$O$2-$O$7)*(1+(($V$2-$W$7)/100*2))+($V$2*2))*0.7) -> 1710 | D51: =INT(C51*3.1) -> 5301 | E51: =INT((($A$2*3+$P$7-$N$2)*(1+(($W$7-$V$2)/100*2))+($W$7*2))*0.7) -> 977 | F51: =INT(E51*3.1) -> 3028
A52: 满修-最小 | B52: 龙卷秒4 | C52: =INT((($A$2*3+$K$2+$O$2-$O$7)*(1+(($V$2-$W$7)/100*2))+($V$2*2))*0.6) -> 1466 | D52: =INT(C52*3.4) -> 4984 | E52: =INT((($A$2*3+$P$7-$N$2)*(1+(($W$7-$V$2)/100*2))+($W$7*2))*0.6) -> 837 | F52: =INT(E52*3.4) -> 2845
A53: 满修-最小 | B53: 龙卷秒5 | C53: =INT((($A$2*3+$K$2+$O$2-$O$7)*(1+(($V$2-$W$7)/100*2))+($V$2*2))*0.5) -> 1222 | D53: =INT(C53*3.5) -> 4277 | E53: =INT((($A$2*3+$P$7-$N$2)*(1+(($W$7-$V$2)/100*2))+($W$7*2))*0.5) -> 698 | F53: =INT(E53*3.5) -> 2443
A54: 满修-最小 | B54: 龙卷秒6 | C54: =INT((($A$2*3+$K$2+$O$2-$O$7)*(1+(($V$2-$W$7)/100*2))+($V$2*2))*0.5) -> 1222 | D54: =INT(C54*4) -> 4888 | E54: =INT((($A$2*3+$P$7-$N$2)*(1+(($W$7-$V$2)/100*2))+($W$7*2))*0.5) -> 698 | F54: =INT(E54*4) -> 2792
A55: 满修-最小 | B55: 龙卷秒7 | C55: =INT((($A$2*3+$K$2+$O$2-$O$7)*(1+(($V$2-$W$7)/100*2))+($V$2*2))*0.5) -> 1222 | D55: =INT(C55*4.5) -> 5499 | E55: =INT((($A$2*3+$P$7-$N$2)*(1+(($W$7-$V$2)/100*2))+($W$7*2))*0.5) -> 698 | F55: =INT(E55*4.5) -> 3141
...

Sheet Sheet2
A1: 等级 | B1: 伤害 | C1: 气血 | D1: 灵力 | E1: 速度 | F1: 防御 | G1: 法防 | H1: 法伤 | I1: 魔法 | J1: 体质 | K1: 魔力 | L1: 力量 | M1: 耐力 | N1: 敏捷 | O1: 修炼 | P1: 血量加成 | Q1: 伤害加成 | R1: 法伤加成 | S1: 速度加成 | T1: 防御加成 | U1: 法防加成
A2: 0 | B2: 80 | C2: 80 | D2: 0 | E2: 15 | F2: 5 | G2: 5 | H2: 25 | I2: 100 | J2: 10 | K2: 10 | L2: 10 | M2: 10 | N2: 10 | O2: =A2*5/20 -> 0 | P2: 1 | Q2: 0.5 | R2: 0.5 | S2: 0.5 | T2: 0.5 | U2: 0.5
A3: 10 | B3: =A3*15 -> 150 | C3: =A3*15 -> 150 | D3: 0 | E3: =A3*2 -> 20 | F3: =A3*6 -> 60 | G3: =A3*4 -> 40 | H3: =A3*8 -> 80 | I3: 200 | J3: 32 | K3: 32 | L3: 50 | M3: 32 | N3: 32 | O3: 0 | P3: 2 | Q3: 0.6 | R3: 0.6 | S3: 0.6 | T3: 0.6 | U3: 0.6
A4: 20 | B4: =A4*15 -> 300 | C4: =A4*15 -> 300 | D4: 0 | E4: =A4*2 -> 40 | F4: =A4*6 -> 120 | G4: =A4*4 -> 80 | H4: =A4*8 -> 160 | I4: 300 | J4: 54 | K4: 54 | L4: 100 | M4: 54 | N4: 54 | O4: 0 | P4: 3 | Q4: 0.7 | R4: 0.7 | S4: 0.7 | T4: 0.7 | U4: 0.7
A5: 30 | B5: =A5*15 -> 450 | C5: =A5*15 -> 450 | D5: 0 | E5: =A5*2 -> 60 | F5: =A5*6 -> 180 | G5: =A5*4 -> 120 | H5: =A5*8 -> 240 | I5: 400 | J5: 76 | K5: 76 | L5: 150 | M5: 76 | N5: 76 | O5: 0 | P5: 4 | Q5: 0.8 | R5: 0.8 | S5: 0.8 | T5: 0.8 | U5: 0.8
A6: 40 | B6: =A6*15 -> 600 | C6: =A6*15 -> 600 | D6: 0 | E6: =A6*2 -> 80 | F6: =A6*6 -> 240 | G6: =A6*4 -> 160 | H6: =A6*8 -> 320 | I6: 500 | J6: 98 | K6: 98 | L6: 200 | M6: 98 | N6: 98 | O6: 0 | P6: 5 | Q6: 0.9 | R6: 0.9 | S6: 0.9 | T6: 0.9 | U6: 0.9
A7: 50 | B7: =A7*15 -> 750 | C7: =A7*15 -> 750 | D7: 0 | E7: =A7*2 -> 100 | F7: =A7*6 -> 300 | G7: =A7*4 -> 200 | H7: =A7*8 -> 400 | I7: 600 | J7: 120 | K7: 120 | L7: 250 | M7: 120 | N7: 120 | O7: 6 | P7: 6 | Q7: 1 | R7: 1 | S7: 1 | T7: 1 | U7: 1
A8: 60 | B8: =A8*15 -> 900 | C8: =A8*15 -> 900 | D8: 0 | E8: =A8*2 -> 120 | F8: =A8*6 -> 360 | G8: =A8*4 -> 240 | H8: =A8*8 -> 480 | I8: 700 | J8: 142 | K8: 142 | L8: 300 | M8: 142 | N8: 142 | O8: 8 | P8: 7 | Q8: 1.1 | R8: 1.1 | S8: 1.1 | T8: 1.1 | U8: 1.1
A9: 70 | B9: =A9*15 -> 1050 | C9: =A9*15 -> 1050 | D9: 0 | E9: =A9*2 -> 140 | F9: =A9*6 -> 420 | G9: =A9*4 -> 280 | H9: =A9*8 -> 560 | I9: 800 | J9: 164 | K9: 164 | L9: 350 | M9: 164 | N9: 164 | O9: 10 | P9: 8 | Q9: 1.2 | R9: 1.2 | S9: 1.2 | T9: 1.2 | U9: 1.2
A10: 80 | B10: =A10*15 -> 1200 | C10: =A10*15 -> 1200 | D10: 0 | E10: =A10*2 -> 160 | F10: =A10*6 -> 480 | G10: =A10*4 -> 320 | H10: =A10*8 -> 640 | I10: 900 | J10: 186 | K10: 186 | L10: 400 | M10: 186 | N10: 186 | O10: 12 | P10: 9 | Q10: 1.3 | R10: 1.3 | S10: 1.3 | T10: 1.3 | U10: 1.3
A11: 90 | B11: =A11*15 -> 1350 | C11: =A11*15 -> 1350 | D11: 0 | E11: =A11*2 -> 180 | F11: =A11*6 -> 540 | G11: =A11*4 -> 360 | H11: =A11*8 -> 720 | I11: 1000 | J11: 208 | K11: 208 | L11: 450 | M11: 208 | N11: 208 | O11: 14 | P11: 10 | Q11: 1.4 | R11: 1.4 | S11: 1.4 | T11: 1.4 | U11: 1.4
A12: 100 | B12: =A12*15 -> 1500 | C12: =A12*15 -> 1500 | D12: 0 | E12: =A12*2 -> 200 | F12: =A12*6 -> 600 | G12: =A12*4 -> 400 | H12: =A12*8 -> 800 | I12: 1100 | J12: 230 | K12: 230 | L12: 500 | M12: 230 | N12: 230 | O12: 16 | P12: 11 | Q12: 1.5 | R12: 1.5 | S12: 1.5 | T12: 1.5 | U12: 1.5
A13: 110 | B13: =A13*15 -> 1650 | C13: =A13*15 -> 1650 | D13: 0 | E13: =A13*2 -> 220 | F13: =A13*6 -> 660 | G13: =A13*4 -> 440 | H13: =A13*8 -> 880 | I13: 1200 | J13: 252 | K13: 252 | L13: 550 | M13: 252 | N13: 252 | O13: 18 | P13: 12 | Q13: 1.6 | R13: 1.6 | S13: 1.6 | T13: 1.6 | U13: 1.6
A14: 120 | B14: =A14*15 -> 1800 | C14: =A14*15 -> 1800 | D14: 0 | E14: =A14*2 -> 240 | F14: =A14*6 -> 720 | G14: =A14*4 -> 480 | H14: =A14*8 -> 960 | I14: 1300 | J14: 274 | K14: 274 | L14: 600 | M14: 274 | N14: 274 | O14: 20 | P14: 13 | Q14: 1.7 | R14: 1.7 | S14: 1.7 | T14: 1.7 | U14: 1.7
... A22: 200 | B22: =A22*15 -> 3000 | C22: =A22*15 -> 3000 | D22: 0 | E22: =A22*2 -> 400 | F22: =A22*6 -> 1200 | G22: =A22*4 -> 800 | H22: =A22*8 -> 1600 | I22: 2100 | J22: 450 | K22: 450 | L22: 1000 | M22: 450 | N22: 450 | O22: 25 | P22: 21 | Q22: 2.5 | R22: 2.5 | S22: 2.5 | T22: 2.5 | U22: 2.5
A26: 人物等级 | B26: 装备最小命中 | C26: 装备最大命中 | D26: 装备最小伤害 | E26: 装备最大伤害 | F26: 装备最小防御 | G26: 装备最大防御 | H26: 装备最小灵力 | I26: 装备最大灵力 | J26: 装备最小气血 | K26: 装备最大气血 | L26: 装备最小敏捷 | M26: 装备最大敏捷 | N26: 最大魔法 | O26: 最小命中 | P26: 最大命中 | Q26: 最小伤害 | R26: 最大伤害 | S26: 最小防御 | T26: 最大防御 | U26: 最小魔法 | V26: 最大魔法 | W26: 最小灵力 | X26: 最大灵力 | Y26: 最小防御 | Z26: 最大防御 | AA26: 最小防御 | AB26: 最大防御 | AC26: 最小气血 | AD26: 最大气血 | AE26: 最小防御 | AF26: 最大防御 | AG26: 最小敏捷 | AH26: 最大敏捷 | AI26: 修炼 | AJ26: 人物等级
A27: 0 | B27: =O27 -> 10 | C27: =P27 -> 13 | D27: =Q27 -> 10 | E27: =R27 -> 14 | F27: =S27+Y27+AA27+AE27 -> 25 | G27: =T27+Z27+AB27+AF27 -> 31 | H27: =W27 -> 5 | I27: =X27 -> 6 | J27: =AC27 -> 10 | K27: =AD27 -> 13 | L27: =AG27 -> 5 | M27: =AH27 -> 6 | N27: =V27 -> 6 | O27: 10 | P27: 13 | Q27: 10 | R27: 14 | S27: 5 | T27: 6 | U27: 5 | V27: 6 | W27: 5 | X27: 6 | Y27: 10 | Z27: 13 | AA27: 5 | AB27: 6 | AC27: 10 | AD27: 13 | AE27: 5 | AF27: 6 | AG27: 5 | AH27: 6 | AI27: 0 | AJ27: 0
A28: 1 | B28: =O28 -> 10 | C28: =P28 -> 13 | D28: =Q28 -> 10 | E28: =R28 -> 14 | F28: =S28+Y28+AA28+AE28 -> 25 | G28: =T28+Z28+AB28+AF28 -> 31 | H28: =W28 -> 5 | I28: =X28 -> 6 | J28: =AC28 -> 10 | K28: =AD28 -> 13 | L28: =AG28 -> 5 | M28: =AH28 -> 6 | N28: =V28 -> 6 | O28: 10 | P28: 13 | Q28: 10 | R28: 14 | S28: 5 | T28: 6 | U28: 5 | V28: 6 | W28: 5 | X28: 6 | Y28: 10 | Z28: 13 | AA28: 5 | AB28: 6 | AC28: 10 | AD28: 13 | AE28: 5 | AF28: 6 | AG28: 5 | AH28: 6 | AI28: 0 | AJ28: 1
A29: 2 | B29: =O29 -> 10 | C29: =P29 -> 13 | D29: =Q29 -> 10 | E29: =R29 -> 14 | F29: =S29+Y29+AA29+AE29 -> 25 | G29: =T29+Z29+AB29+AF29 -> 31 | H29: =W29 -> 5 | I29: =X29 -> 6 | J29: =AC29 -> 10 | K29: =AD29 -> 13 | L29: =AG29 -> 5 | M29: =AH29 -> 6 | N29: =V29 -> 6 | O29: 10 | P29: 13 | Q29: 10 | R29: 14 | S29: 5 | T29: 6 | U29: 5 | V29: 6 | W29: 5 | X29: 6 | Y29: 10 | Z29: 13 | AA29: 5 | AB29: 6 | AC29: 10 | AD29: 13 | AE29: 5 | AF29: 6 | AG29: 5 | AH29: 6 | AI29: 0 | AJ29: 2
A30: 3 | B30: =O30 -> 10 | C30: =P30 -> 13 | D30: =Q30 -> 10 | E30: =R30 -> 14 | F30: =S30+Y30+AA30+AE30 -> 25 | G30: =T30+Z30+AB30+AF30 -> 31 | H30: =W30 -> 5 | I30: =X30 -> 6 | J30: =AC30 -> 10 | K30: =AD30 -> 13 | L30: =AG30 -> 5 | M30: =AH30 -> 6 | N30: =V30 -> 6 | O30: 10 | P30: 13 | Q30: 10 | R30: 14 | S30: 5 | T30: 6 | U30: 5 | V30: 6 | W30: 5 | X30: 6 | Y30: 10 | Z30: 13 | AA30: 5 | AB30: 6 | AC30: 10 | AD30: 13 | AE30: 5 | AF30: 6 | AG30: 5 | AH30: 6 | AI30: 0 | AJ30: 3
A31: 4 | B31: =O31 -> 10 | C31: =P31 -> 13 | D31: =Q31 -> 10 | E31: =R31 -> 14 | F31: =S31+Y31+AA31+AE31 -> 25 | G31: =T31+Z31+AB31+AF31 -> 31 | H31: =W31 -> 5 | I31: =X31 -> 6 | J31: =AC31 -> 10 | K31: =AD31 -> 13 | L31: =AG31 -> 5 | M31: =AH31 -> 6 | N31: =V31 -> 6 | O31: 10 | P31: 13 | Q31: 10 | R31: 14 | S31: 5 | T31: 6 | U31: 5 | V31: 6 | W31: 5 | X31: 6 | Y31: 10 | Z31: 13 | AA31: 5 | AB31: 6 | AC31: 10 | AD31: 13 | AE31: 5 | AF31: 6 | AG31: 5 | AH31: 6 | AI31: 0 | AJ31: 4
A32: 5 | B32: =O32 -> 10 | C32: =P32 -> 13 | D32: =Q32 -> 10 | E32: =R32 -> 14 | F32: =S32+Y32+AA32+AE32 -> 25 | G32: =T32+Z32+AB32+AF32 -> 31 | H32: =W32 -> 5 | I32: =X32 -> 6 | J32: =AC32 -> 10 | K32: =AD32 -> 13 | L32: =AG32 -> 5 | M32: =AH32 -> 6 | N32: =V32 -> 6 | O32: 10 | P32: 13 | Q32: 10 | R32: 14 | S32: 5 | T32: 6 | U32: 5 | V32: 6 | W32: 5 | X32: 6 | Y32: 10 | Z32: 13 | AA32: 5 | AB32: 6 | AC32: 10 | AD32: 13 | AE32: 5 | AF32: 6 | AG32: 5 | AH32: 6 | AI32: 0 | AJ32: 5
A33: 6 | B33: =O33 -> 10 | C33: =P33 -> 13 | D33: =Q33 -> 10 | E33: =R33 -> 14 | F33: =S33+Y33+AA33+AE33 -> 25 | G33: =T33+Z33+AB33+AF33 -> 31 | H33: =W33 -> 5 | I33: =X33 -> 6 | J33: =AC33 -> 10 | K33: =AD33 -> 13 | L33: =AG33 -> 5 | M33: =AH33 -> 6 | N33: =V33 -> 6 | O33: 10 | P33: 13 | Q33: 10 | R33: 14 | S33: 5 | T33: 6 | U33: 5 | V33: 6 | W33: 5 | X33: 6 | Y33: 10 | Z33: 13 | AA33: 5 | AB33: 6 | AC33: 10 | AD33: 13 | AE33: 5 | AF33: 6 | AG33: 5 | AH33: 6 | AI33: 0 | AJ33: 6
A34: 7 | B34: =O34 -> 10 | C34: =P34 -> 13 | D34: =Q34 -> 10 | E34: =R34 -> 14 | F34: =S34+Y34+AA34+AE34 -> 25 | G34: =T34+Z34+AB34+AF34 -> 31 | H34: =W34 -> 5 | I34: =X34 -> 6 | J34: =AC34 -> 10 | K34: =AD34 -> 13 | L34: =AG34 -> 5 | M34: =AH34 -> 6 | N34: =V34 -> 6 | O34: 10 | P34: 13 | Q34: 10 | R34: 14 | S34: 5 | T34: 6 | U34: 5 | V34: 6 | W34: 5 | X34: 6 | Y34: 10 | Z34: 13 | AA34: 5 | AB34: 6 | AC34: 10 | AD34: 13 | AE34: 5 | AF34: 6 | AG34: 5 | AH34: 6 | AI34: 0 | AJ34: 7
A35: 8 | B35: =O35 -> 10 | C35: =P35 -> 13 | D35: =Q35 -> 10 | E35: =R35 -> 14 | F35: =S35+Y35+AA35+AE35 -> 25 | G35: =T35+Z35+AB35+AF35 -> 31 | H35: =W35 -> 5 | I35: =X35 -> 6 | J35: =AC35 -> 10 | K35: =AD35 -> 13 | L35: =AG35 -> 5 | M35: =AH35 -> 6 | N35: =V35 -> 6 | O35: 10 | P35: 13 | Q35: 10 | R35: 14 | S35: 5 | T35: 6 | U35: 5 | V35: 6 | W35: 5 | X35: 6 | Y35: 10 | Z35: 13 | AA35: 5 | AB35: 6 | AC35: 10 | AD35: 13 | AE35: 5 | AF35: 6 | AG35: 5 | AH35: 6 | AI35: 0 | AJ35: 8
A36: 9 | B36: =O36 -> 10 | C36: =P36 -> 13 | D36: =Q36 -> 10 | E36: =R36 -> 14 | F36: =S36+Y36+AA36+AE36 -> 25 | G36: =T36+Z36+AB36+AF36 -> 31 | H36: =W36 -> 5 | I36: =X36 -> 6 | J36: =AC36 -> 10 | K36: =AD36 -> 13 | L36: =AG36 -> 5 | M36: =AH36 -> 6 | N36: =V36 -> 6 | O36: 10 | P36: 13 | Q36: 10 | R36: 14 | S36: 5 | T36: 6 | U36: 5 | V36: 6 | W36: 5 | X36: 6 | Y36: 10 | Z36: 13 | AA36: 5 | AB36: 6 | AC36: 10 | AD36: 13 | AE36: 5 | AF36: 6 | AG36: 5 | AH36: 6 | AI36: 0 | AJ36: 9
A37: 10 | B37: =O37 -> 47 | C37: =P37 -> 60 | D37: =Q37 -> 42 | E37: =R37 -> 54 | F37: =S37+Y37+AA37+AE37 -> 56 | G37: =T37+Z37+AB37+AF37 -> 72 | H37: =W37 -> 17 | I37: =X37 -> 23 | J37: =AC37 -> 31 | K37: =AD37 -> 40 | L37: =AG37 -> 8 | M37: =AH37 -> 10 | N37: =V37 -> 20 | O37: 47 | P37: 60 | Q37: 42 | R37: 54 | S37: 10 | T37: 13 | U37: 15 | V37: 20 | W37: 17 | X37: 23 | Y37: 26 | Z37: 33 | AA37: 10 | AB37: 13 | AC37: 31 | AD37: 40 | AE37: 10 | AF37: 13 | AG37: 8 | AH37: 10 | AI37: 0 | AJ37: 10
A38: 11 | B38: =O38 -> 47 | C38: =P38 -> 60 | D38: =Q38 -> 42 | E38: =R38 -> 54 | F38: =S38+Y38+AA38+AE38 -> 56 | G38: =T38+Z38+AB38+AF38 -> 72 | H38: =W38 -> 17 | I38: =X38 -> 23 | J38: =AC38 -> 31 | K38: =AD38 -> 40 | L38: =AG38 -> 8 | M38: =AH38 -> 10 | N38: =V38 -> 20 | O38: 47 | P38: 60 | Q38: 42 | R38: 54 | S38: 10 | T38: 13 | U38: 15 | V38: 20 | W38: 17 | X38: 23 | Y38: 26 | Z38: 33 | AA38: 10 | AB38: 13 | AC38: 31 | AD38: 40 | AE38: 10 | AF38: 13 | AG38: 8 | AH38: 10 | AI38: 0 | AJ38: 11
... A202: 175 | B202: =O202 -> 571 | C202: =P202 -> 777 | D202: =Q202 -> 490 | E202: =R202 -> 667 | F202: =S202+Y202+AA202+AE202 -> 501 | G202: =T202+Z202+AB202+AF202 -> 685 | H202: =W202 -> 196 | I202: =X202 -> 267 | J202: =AC202 -> 329 | K202: =AD202 -> 449 | L202: =AG202 -> 52 | M202: =AH202 -> 70 | N202: =V202 -> 224 | O202: 571 | P202: 777 | Q202: 490 | R202: 667 | S202: 84 | T202: 115 | U202: 163 | V202: 224 | W202: 196 | X202: 267 | Y202: 249 | Z202: 340 | AA202: 84 | AB202: 115 | AC202: 329 | AD202: 449 | AE202: 84 | AF202: 115 | AG202: 52 | AH202: 70 | AI202: 25 | AJ202: 175
A203: 种族 | B203: 命中 | C203: 伤害 | D203: 防御 | E203: 气血 | F203: 法力 | G203: 附加命中 | H203: 附加伤害
A204: 人 | B204: 2 | C204: 0.7 | D204: 1.5 | E204: 5 | F204: 3 | G204: 30 | H204: 34
A205: 魔 | B205: 2.3 | C205: 0.8 | D205: 1.3 | E205: 6 | F205: 3.5 | G205: 29 | H205: 34
A206: 仙 | B206: 1.7 | C206: 0.6 | D206: 1.6 | E206: 4.5 | F206: 3.5 | G206: 30 | H206: 40
A207: 加点方式 | B207: 体质 | C207: 魔力 | D207: 力量 | E207: 耐力 | F207: 敏捷
A208: 全力 | B208: 1 | C208: 1 | D208: 6 | E208: 1 | F208: 1
A209: 力血 | B209: 3 | C209: 1 | D209: 4 | E209: 1 | F209: 1
A210: 血力 | B210: 4 | C210: 1 | D210: 3 | E210: 1 | F210: 1
A211: 力耐 | B211: 1 | C211: 1 | D211: 4 | E211: 3 | F211: 1
A212: 耐力 | B212: 1 | C212: 1 | D212: 3 | E212: 4 | F212: 1
A213: 全魔 | B213: 1 | C213: 6 | D213: 1 | E213: 1 | F213: 1
...
